Workbook

Sheet sequence-1-simulation-1
A1: Class | B1: Method | C1: Runtime | D1: Calls | E1: Average | F1: Class | G1: Method | H1: Runtime | I1: Calls | J1: Average | K1: Class | L1: Method | M1: Runtime | N1: Calls | O1: Average
A2: BBoxSphere | B2: CheckOBB | C2: 570628.8 | D2: 4332776 | E2: 0.13170051 | F2: SBC | G2: CheckSOBR | H2: 4347972.9 | I2: 4332776 | J2: 1.0035074 | K2: SBCA1 | L2: CheckSOBRA1 | M2: 1025448.1 | N2: 4332776 | O2: 0.23667231
A3: BBoxSphere | B3: CheckSphere | C3: 192951.9 | D3: 3836730 | E3: 0.050290716 | F3: SBC | G3: CheckSBC | H3: 434425.1 | I3: 3836730 | J3: 0.11322796 | K3: SBCA1 | L3: CheckSBCA1 | M3: 172325.2 | N3: 3836730 | O3: 0.044914602
A4: BBoxSphere | B4: Reorient | C4: 109328.2 | D4: 562810 | E4: 0.19425419 | F4: SBC | G4: Reorient | H4: 107583.9 | I4: 562810 | J4: 0.19115492 | K4: SBCA1 | L4: Reorient | M4: 111478.1 | N4: 562810 | O4: 0.19807413
A5: BBoxSphere | B5: Reposition | C5: 39974 | D5: 562810 | E5: 0.071025746 | F5: SBC | G5: Reposition | H5: 36014.7 | I5: 562810 | J5: 0.063990867 | K5: SBCA1 | L5: Reposition | M5: 37366.9 | N5: 562810 | O5: 0.066393454
A6: BBoxSphere | B6: Resize | C6: 20360.4 | D6: 562810 | E6: 0.036176329 | F6: SBC | G6: Resize | H6: 21611.8 | I6: 562810 | J6: 0.038399815 | K6: SBCA1 | L6: Resize | M6: 22486.4 | N6: 562810 | O6: 0.039953803
A7: BBoxSphere | B7: UpdateSimpleSize | C7: 16478.6 | D7: 562810 | E7: 0.029279153 | F7: SBC | G7: UpdateSimpleSize | H7: 15653.9 | I7: 562810 | J7: 0.027813827 | K7: SBCA1 | L7: UpdateSimpleSize | M7: 16074.6 | N7: 562810 | O7: 0.028561326
A8: OBBox | B8: CheckOBB | C8: 3239968.2 | D8: 1837830 | E8: 1.7629314 | F8: SOBR | G8: CheckSOBR | H8: 1341359.6 | I8: 1837830 | J8: 0.72986054 | K8: SOBRA1 | L8: CheckSOBRA1 | M8: 1132940.4 | N8: 1837830 | O8: 0.61645549
A9: OBBox | B9: CheckSphere | C9: 267931.4 | D9: 2034414 | E9: 0.13169955 | F9: SOBR | G9: CheckSBC | H9: 2176276.2 | I9: 2034414 | J9: 1.0697312 | K9: SOBRA1 | L9: CheckSBCA1 | M9: 515506.8 | N9: 2034414 | O9: 0.25339326
A10: OBBox | B10: Reorient | C10: 112653.6 | D10: 559700 | E10: 0.20127497 | F10: SOBR | G10: Reorient | H10: 264517.6 | I10: 559700 | J10: 0.47260604 | K10: SOBRA1 | L10: Reorient | M10: 416644.7 | N10: 559700 | O10: 0.74440718
A11: OBBox | B11: Reposition | C11: 45414.3 | D11: 559700 | E11: 0.081140432 | F11: SOBR | G11: Reposition | H11: 47588.2 | I11: 559700 | J11: 0.085024477 | K11: SOBRA1 | L11: Reposition | M11: 46025.1 | N11: 559700 | O11: 0.082231731
A12: OBBox | B12: Resize | C12: 22847.3 | D12: 559700 | E12: 0.040820618 | F12: SOBR | G12: Resize | H12: 26758 | I12: 559700 | J12: 0.047807754 | K12: SOBRA1 | L12: Resize | M12: 27609.9 | N12: 559700 | O12: 0.04932982
A13: OBBox | B13: UpdateSimpleSize | C13: 93576.2 | D13: 559700 | E13: 0.16718992 | F13: SOBR | G13: UpdateSimpleSize | H13: 90399.3 | I13: 559700 | J13: 0.16151385 | K13: SOBRA1 | L13: UpdateSimpleSize | M13: 94168.9 | N13: 559700 | O13: 0.16824888
... A15: Octree`1 | B15: Contains | C15: 464040.8 | D15: 8540580 | E15: 0.05433364 | F15: Octree`1 | G15: Contains | H15: 455219.5 | I15: 8540580 | J15: 0.053300771 | K15: Octree`1 | L15: Contains | M15: 469244.3 | N15: 8540580 | O15: 0.054942908
A16: Sum | C16: 10559269 | D16: 120635800 | E16: 0.087530147 | F16: Sum | H16: 14635296 | I16: 120635800 | J16: 0.12131802 | K16: Sum | M16: 9503113.3 | N16: 120635800 | O16: 0.078775233
A17: Total time elapsed (μs) | C17: 1.8274058e+08 | F17: Total time elapsed (μs) | H17: 182509568 | K17: Total time elapsed (μs) | M17: 1.8262098e+08
A19: Class | B19: Euclidean | C19: Baseline | D19: Artifact | F19: Method | G19: SBC.CheckSOBR | H19: SBC.CheckSBC | I19: SBC.Reorient | J19: SBC.Reposition | K19: SBC.Resize | L19: SBC.UpdateSimpleSize | M19: SOBR.CheckSOBR | N19: SOBR.CheckSBC | O19: SOBR.Reorient | P19: SOBR.Reposition | Q19: SOBR.Resize | R19: SOBR.UpdateSimpleSize | S19: Simple.Intersects | T19: CollisionTree.Contains
A20: SBC.CheckSOBR | B20: {=$E$2:$E$16} -> 0.13170051 | C20: {=$J$2:$J$16} -> 1.0035074 | D20: {=$O$2:$O$16} -> 0.23667231 | F20: Euclidean | G20: {=TRANSPOSE($C$2:$C$15/1000000)} -> 0.5706288 | H20: 0.1929519 | I20: 0.1093282 | J20: 0.039974 | K20: 0.0203604 | L20: 0.0164786 | M20: 3.2399682 | N20: 0.2679314 | O20: 0.1126536 | P20: 0.0454143 | Q20: 0.0228473 | R20: 0.0935762 | S20: 5.3631156 | T20: 0.4640408
A21: SBC.CheckSBC | B21: 0.050290716 | C21: 0.11322796 | D21: 0.044914602 | F21: Baseline | G21: {=TRANSPOSE($H$2:$H$15/1000000)} -> 4.3479729 | H21: 0.4344251 | I21: 0.1075839 | J21: 0.0360147 | K21: 0.0216118 | L21: 0.0156539 | M21: 1.3413596 | N21: 2.1762762 | O21: 0.2645176 | P21: 0.0475882 | Q21: 0.026758 | R21: 0.0903993 | S21: 5.2699155 | T21: 0.4552195
A22: SBC.Reorient | B22: 0.19425419 | C22: 0.19115492 | D22: 0.19807413 | F22: Artifact | G22: {=TRANSPOSE($M$2:$M$15/1000000)} -> 1.0254481 | H22: 0.1723252 | I22: 0.1114781 | J22: 0.0373669 | K22: 0.0224864 | L22: 0.0160746 | M22: 1.1329404 | N22: 0.5155068 | O22: 0.4166447 | P22: 0.0460251 | Q22: 0.0276099 | R22: 0.0941689 | S22: 5.4157939 | T22: 0.4692443
A23: SBC.Reposition | B23: 0.071025746 | C23: 0.063990867 | D23: 0.066393454
A24: SBC.Resize | B24: 0.036176329 | C24: 0.038399815 | D24: 0.039953803 | F24: Function | G24: Sequence 1 calls | O24: Euclidean | P24: Baseline | Q24: Artifact | R24: Runtimes | S24: Euclidean | T24: Baseline | U24: Artifact
A25: SBC.UpdateSimpleSize | B25: 0.029279153 | C25: 0.027813827 | D25: 0.028561326 | F25: SBC.CheckSOBR | G25: =$D$2 -> 4332776 | O25: =SUM($C$4:$C$7,$C$10:$C$13) -> 460632.6 | P25: =SUM($H$4:$H$7,$H$10:$H$13) -> 610127.4 | Q25: =SUM($M$4:$M$7,$M$10:$M$13) -> 771854.6 | R25: Update phase | S25: {=$O$25:$O$29/$P$25:$P$29} -> 0.75497773 | T25: 1 | U25: {=$Q$25:$Q$29/$P$25:$P$29} -> 1.2650712
A26: SOBR.CheckSOBR | B26: 1.7629314 | C26: 0.72986054 | D26: 0.61645549 | F26: SBC.CheckSBC | G26: =$D$3 -> 3836730 | O26: =SUM($C$2,$C$3,$C$8,$C$9) -> 4271480.3 | P26: =SUM($H$2,$H$3,$H$8,$H$9) -> 8300033.8 | Q26: =SUM($M$2,$M$3,$M$8,$M$9) -> 2846220.5 | R26: Narrow phase | S26: 0.51463408 | T26: 1 | U26: 0.34291674
A27: SOBR.CheckSBC | B27: 0.13169955 | C27: 1.0697312 | D27: 0.25339326 | F27: SOBR.CheckSOBR | G27: =$D$8 -> 1837830 | O27: =SUM($C$14,$C$15) -> 5827156.4 | P27: =SUM($H$14,$H$15) -> 5725135 | Q27: =SUM($M$14,$M$15) -> 5885038.2 | R27: Broad phase | S27: 1.0178199 | T27: 1 | U27: 1.02793
A28: SOBR.Reorient | B28: 0.20127497 | C28: 0.47260604 | D28: 0.74440718 | F28: SOBR.CheckSBC | G28: =$D$9 -> 2034414 | O28: =$C$16 -> 10559269 | P28: =$H$16 -> 14635296 | Q28: =$M$16 -> 9503113.3 | R28: Combined | S28: 0.72149338 | T28: 1 | U28: 0.64932839
A29: SOBR.Reposition | B29: 0.081140432 | C29: 0.085024477 | D29: 0.082231731 | F29: Sum | G29: =SUM($G$25:$G$28) -> 12041750 | O29: =$C$17 -> 1.8274058e+08 | P29: =$H$17 -> 182509568 | Q29: =$M$17 -> 1.8262098e+08 | R29: Entire simulation | S29: 1.0012658 | T29: 1 | U29: 1.0006104
A30: SOBR.Resize | B30: 0.040820618 | C30: 0.047807754 | D30: 0.04932982
A31: SOBR.UpdateSimpleSize | B31: 0.16718992 | C31: 0.16151385 | D31: 0.16824888
A32: Simple.Intersects | B32: 0.056121004 | C32: 0.055145734 | D32: 0.056672243
A33: CollisionTree.Contains | B33: 0.05433364 | C33: 0.053300771 | D33: 0.054942908
A34: Sum | B34: 0.087530147 | C34: 0.12131802 | D34: 0.078775233
A35: Total time elapsed

Sheet sequence-2-simulation-1
A1: Class | B1: Method | C1: Runtime | D1: Calls | E1: Average | F1: Class | G1: Method | H1: Runtime | I1: Calls | J1: Average | K1: Class | L1: Method | M1: Runtime | N1: Calls | O1: Average
A2: BBoxSphere | B2: CheckOBB | C2: 9231241.6 | D2: 78233950 | E2: 0.11799534 | F2: SBC | G2: CheckSOBR | H2: 75755255 | I2: 78233950 | J2: 0.96831688 | K2: SBCA1 | L2: CheckSOBRA1 | M2: 16391701 | N2: 78233950 | O2: 0.20952158
A3: BBoxSphere | B3: CheckSphere | C3: 3807628.1 | D3: 84091350 | E3: 0.045279664 | F3: SBC | G3: CheckSBC | H3: 8783811.2 | I3: 84091350 | J3: 0.10445559 | K3: SBCA1 | L3: CheckSBCA1 | M3: 3432520.7 | N3: 84091350 | O3: 0.040818951
A4: BBoxSphere | B4: Reorient | C4: 1018309.6 | D4: 5814230 | E4: 0.17514092 | F4: SBC | G4: Reorient | H4: 966183.3 | I4: 5814230 | J4: 0.16617562 | K4: SBCA1 | L4: Reorient | M4: 1008949.6 | N4: 5814230 | O4: 0.17353108
A5: BBoxSphere | B5: Reposition | C5: 324798 | D5: 5814230 | E5: 0.055862599 | F5: SBC | G5: Reposition | H5: 301415.1 | I5: 5814230 | J5: 0.051840932 | K5: SBCA1 | L5: Reposition | M5: 295084.7 | N5: 5814230 | O5: 0.050752155
A6: BBoxSphere | B6: Resize | C6: 189204.5 | D6: 5814230 | E6: 0.032541626 | F6: SBC | G6: Resize | H6: 191482.6 | I6: 5814230 | J6: 0.032933441 | K6: SBCA1 | L6: Resize | M6: 191587.3 | N6: 5814230 | O6: 0.032951448
A7: BBoxSphere | B7: UpdateSimpleSize | C7: 146008.1 | D7: 5814230 | E7: 0.025112199 | F7: SBC | G7: UpdateSimpleSize | H7: 141976.2 | I7: 5814230 | J7: 0.024418745 | K7: SBCA1 | L7: UpdateSimpleSize | M7: 141335.2 | N7: 5814230 | O7: 0.024308498
A8: OBBox | B8: CheckOBB | C8: 89113733 | D8: 54315320 | E8: 1.640674 | F8: SOBR | G8: CheckSOBR | H8: 36246220 | I8: 54315320 | J8: 0.66732959 | K8: SOBRA1 | L8: CheckSOBRA1 | M8: 29365782 | N8: 54315320 | O8: 0.54065375
A9: OBBox | B9: CheckSphere | C9: 7182652.9 | D9: 61132190 | E9: 0.11749379 | F9: SOBR | G9: CheckSBC | H9: 58071525 | I9: 61132190 | J9: 0.94993366 | K9: SOBRA1 | L9: CheckSBCA1 | M9: 12710935 | N9: 61132190 | O9: 0.20792539
A10: OBBox | B10: Reorient | C10: 1156948.4 | D10: 6624050 | E10: 0.17465877 | F10: SOBR | G10: Reorient | H10: 2998324.3 | I10: 6624050 | J10: 0.45264216 | K10: SOBRA1 | L10: Reorient | M10: 4930522.7 | N10: 6624050 | O10: 0.74433658
A11: OBBox | B11: Reposition | C11: 373583.2 | D11: 6624050 | E11: 0.056398004 | F11: SOBR | G11: Reposition | H11: 352960.9 | I11: 6624050 | J11: 0.053284758 | K11: SOBRA1 | L11: Reposition | M11: 338892.6 | N11: 6624050 | O11: 0.051160936
A12: OBBox | B12: Resize | C12: 218467.3 | D12: 6624050 | E12: 0.032980926 | F12: SOBR | G12: Resize | H12: 220749.8 | I12: 6624050 | J12: 0.033325503 | K12: SOBRA1 | L12: Resize | M12: 219682.1 | N12: 6624050 | O12: 0.033164318
A13: OBBox | B13: UpdateSimpleSize | C13: 904030.6 | D13: 6624050 | E13: 0.13647702 | F13: SOBR | G13: UpdateSimpleSize | H13: 880784.6 | I13: 6624050 | J13: 0.13296769 | K13: SOBRA1 | L13: UpdateSimpleSize | M13: 869787.8 | N13: 6624050 | O13: 0.13130755
... A15: Octree`1 | B15: Contains | C15: 6416201.5 | D15: 135038200 | E15: 0.047513974 | F15: Octree`1 | G15: Contains | H15: 6400549.5 | I15: 135038200 | J15: 0.047398066 | K15: Octree`1 | L15: Contains | M15: 6395631.2 | N15: 135038200 | O15: 0.047361644
A16: Sum | C16: 4.0816168e+08 | D16: 6881220144 | E16: 0.059315307 | F16: Sum | H16: 4.7936518e+08 | I16: 6881220144 | J16: 0.069662817 | K16: Sum | M16: 3.6499843e+08 | N16: 6881220144 | O16: 0.05304269
A17: Total time elapsed (μs) | C17: 2.0735246e+09 | F17: Total time elapsed (μs) | H17: 2.1296054e+09 | K17: Total time elapsed (μs) | M17: 2014691328
A19: Class | B19: Euclidean | C19: Baseline | D19: Artifact | F19: Method | G19: SBC.CheckSOBR | H19: SBC.CheckSBC | I19: SBC.Reorient | J19: SBC.Reposition | K19: SBC.Resize | L19: SBC.UpdateSimpleSize | M19: SOBR.CheckSOBR | N19: SOBR.CheckSBC | O19: SOBR.Reorient | P19: SOBR.Reposition | Q19: SOBR.Resize | R19: SOBR.UpdateSimpleSize | S19: Simple.Intersects | T19: CollisionTree.Contains
A20: SBC.CheckSOBR | B20: {=$E$2:$E$16} -> 0.11799534 | C20: {=$J$2:$J$16} -> 0.96831688 | D20: {=$O$2:$O$16} -> 0.20952158 | F20: Euclidean | G20: {=TRANSPOSE($C$2:$C$15/1000000)} -> 9.2312416 | H20: 3.8076281 | I20: 1.0183096 | J20: 0.324798 | K20: 0.1892045 | L20: 0.1460081 | M20: 89.113733 | N20: 7.1826529 | O20: 1.1569484 | P20: 0.3735832 | Q20: 0.2184673 | R20: 0.9040306 | S20: 288.07888 | T20: 6.4162015
A21: SBC.CheckSBC | B21: 0.045279664 | C21: 0.10445559 | D21: 0.040818951 | F21: Baseline | G21: {=TRANSPOSE($H$2:$H$15/1000000)} -> 75.755255 | H21: 8.7838112 | I21: 0.9661833 | J21: 0.3014151 | K21: 0.1914826 | L21: 0.1419762 | M21: 36.24622 | N21: 58.071525 | O21: 2.9983243 | P21: 0.3529609 | Q21: 0.2207498 | R21: 0.8807846 | S21: 288.05394 | T21: 6.4005495
A22: SBC.Reorient | B22: 0.17514092 | C22: 0.16617562 | D22: 0.17353108 | F22: Artifact | G22: {=TRANSPOSE($M$2:$M$15/1000000)} -> 16.391701 | H22: 3.4325207 | I22: 1.0089496 | J22: 0.2950847 | K22: 0.1915873 | L22: 0.1413352 | M22: 29.365782 | N22: 12.710935 | O22: 4.9305227 | P22: 0.3388926 | Q22: 0.2196821 | R22: 0.8697878 | S22: 288.70601 | T22: 6.3956312
A23: SBC.Reposition | B23: 0.055862599 | C23: 0.051840932 | D23: 0.050752155
A24: SBC.Resize | B24: 0.032541626 | C24: 0.032933441 | D24: 0.032951448 | F24: Function | G24: Sequence 2 calls | O24: Euclidean | P24: Baseline | Q24: Artifact | R24: Runtimes | S24: Euclidean | T24: Baseline | U24: Artifact
A25: SBC.UpdateSimpleSize | B25: 0.025112199 | C25: 0.024418745 | D25: 0.024308498 | F25: SBC.CheckSOBR | G25: =$D$2 -> 78233950 | O25: =SUM($C$4:$C$7,$C$10:$C$13) -> 4331349.7 | P25: =SUM($H$4:$H$7,$H$10:$H$13) -> 6053876.8 | Q25: =SUM($M$4:$M$7,$M$10:$M$13) -> 7995842 | R25: Update phase | S25: {=$O$25:$O$29/$P$25:$P$29} -> 0.7154671 | T25: 1 | U25: {=$Q$25:$Q$29/$P$25:$P$29} -> 1.3207804
A26: SOBR.CheckSOBR | B26: 1.640674 | C26: 0.66732959 | D26: 0.54065375 | F26: SBC.CheckSBC | G26: =$D$3 -> 84091350 | O26: =SUM($C$2,$C$3,$C$8,$C$9) -> 1.0933526e+08 | P26: =SUM($H$2,$H$3,$H$8,$H$9) -> 1.7885681e+08 | Q26: =SUM($M$2,$M$3,$M$8,$M$9) -> 61900938 | R26: Narrow phase | S26: 0.61130049 | T26: 1 | U26: 0.34609215
A27: SOBR.CheckSBC | B27: 0.11749379 | C27: 0.94993366 | D27: 0.20792539 | F27: SOBR.CheckSOBR | G27: =$D$8 -> 54315320 | O27: =SUM($C$14,$C$15) -> 294495078 | P27: =SUM($H$14,$H$15) -> 294454494 | Q27: =SUM($M$14,$M$15) -> 2.9510165e+08 | R27: Broad phase | S27: 1.0001378 | T27: 1 | U27: 1.0021978
A28: SOBR.Reorient | B28: 0.17465877 | C28: 0.45264216 | D28: 0.74433658 | F28: SOBR.CheckSBC | G28: =$D$9 -> 61132190 | O28: =$C$16 -> 4.0816168e+08 | P28: =$H$16 -> 4.7936518e+08 | Q28: =$M$16 -> 3.6499843e+08 | R28: Combined | S28: 0.85146293 | T28: 1 | U28: 0.76142039
A29: SOBR.Reposition | B29: 0.056398004 | C29: 0.053284758 | D29: 0.051160936 | F29: Sum | G29: =SUM($G$25:$G$28) -> 277772810 | O29: =$C$17 -> 2.0735246e+09 | P29: =$H$17 -> 2.1296054e+09 | Q29: =$M$17 -> 2014691328 | R29: Entire simulation | S29: 0.97366611 | T29: 1 | U29: 0.94603972
A30: SOBR.Resize | B30: 0.032980926 | C30: 0.033325503 | D30: 0.033164318
A31: SOBR.UpdateSimpleSize | B31: 0.13647702 | C31: 0.13296769 | D31: 0.13130755
A32: Simple.Intersects | B32: 0.044881495 | C32: 0.04487761 | D32: 0.0449792
A33: CollisionTree.Contains | B33: 0.047513974 | C33: 0.047398066 | D33: 0.047361644
A34: Sum | B34: 0.059315307 | C34: 0.069662817 | D34: 0.05304269
A35: Total time elapsed

Sheet sequence-3-simulation-1
A1: Class | B1: Method | C1: Runtime | D1: Calls | E1: Average | F1: Class | G1: Method | H1: Runtime | I1: Calls | J1: Average | K1: Class | L1: Method | M1: Runtime | N1: Calls | O1: Average
A2: BBoxSphere | B2: CheckOBB | C2: 10229298 | D2: 86413296 | E2: 0.11837644 | F2: SBC | G2: CheckSOBR | H2: 84130522 | I2: 86413296 | J2: 0.97358308 | K2: SBCA1 | L2: CheckSOBRA1 | M2: 18310669 | N2: 86413296 | O2: 0.21189643
A3: BBoxSphere | B3: CheckSphere | C3: 4948657.7 | D3: 109741450 | E3: 0.045093788 | F3: SBC | G3: CheckSBC | H3: 11404762 | I3: 109741450 | J3: 0.10392392 | K3: SBCA1 | L3: CheckSBCA1 | M3: 4485137.7 | N3: 109741450 | O3: 0.040870042
A4: BBoxSphere | B4: Reorient | C4: 2127695.5 | D4: 12222800 | E4: 0.17407595 | F4: SBC | G4: Reorient | H4: 2005748 | I4: 12222800 | J4: 0.1640989 | K4: SBCA1 | L4: Reorient | M4: 2116858.2 | N4: 12222800 | O4: 0.1731893
A5: BBoxSphere | B5: Reposition | C5: 662802.6 | D5: 12222800 | E5: 0.05422674 | F5: SBC | G5: Reposition | H5: 616737.2 | I5: 12222800 | J5: 0.050457931 | K5: SBCA1 | L5: Reposition | M5: 625669.6 | N5: 12222800 | O5: 0.051188729
A6: BBoxSphere | B6: Resize | C6: 395030.1 | D6: 12222800 | E6: 0.032319117 | F6: SBC | G6: Resize | H6: 392155.6 | I6: 12222800 | J6: 0.032083941 | K6: SBCA1 | L6: Resize | M6: 395500.3 | N6: 12222800 | O6: 0.032357586
A7: BBoxSphere | B7: UpdateSimpleSize | C7: 303967.9 | D7: 12222800 | E7: 0.024868925 | F7: SBC | G7: UpdateSimpleSize | H7: 297609.7 | I7: 12222800 | J7: 0.024348734 | K7: SBCA1 | L7: UpdateSimpleSize | M7: 296007.1 | N7: 12222800 | O7: 0.024217618
A8: OBBox | B8: CheckOBB | C8: 73565602 | D8: 43854870 | E8: 1.6774785 | F8: SOBR | G8: CheckSOBR | H8: 29807274 | I8: 43854870 | J8: 0.67967991 | K8: SOBRA1 | L8: CheckSOBRA1 | M8: 23947686 | N8: 43854870 | O8: 0.54606675
A9: OBBox | B9: CheckSphere | C9: 7022439.4 | D9: 58883024 | E9: 0.11926085 | F9: SOBR | G9: CheckSBC | H9: 56277155 | I9: 58883024 | J9: 0.95574499 | K9: SOBRA1 | L9: CheckSBCA1 | M9: 12374986 | N9: 58883024 | O9: 0.21016221
A10: OBBox | B10: Reorient | C10: 2032021 | D10: 11647370 | E10: 0.17446179 | F10: SOBR | G10: Reorient | H10: 5799673.9 | I10: 11647370 | J10: 0.4979385 | K10: SOBRA1 | L10: Reorient | M10: 9624938.9 | N10: 11647370 | O10: 0.82636156
A11: OBBox | B11: Reposition | C11: 657975.5 | D11: 11647370 | E11: 0.056491337 | F11: SOBR | G11: Reposition | H11: 613434.8 | I11: 11647370 | J11: 0.052667237 | K11: SOBRA1 | L11: Reposition | M11: 615805.1 | N11: 11647370 | O11: 0.052870742
A12: OBBox | B12: Resize | C12: 383820.8 | D12: 11647370 | E12: 0.032953431 | F12: SOBR | G12: Resize | H12: 388116 | I12: 11647370 | J12: 0.033322201 | K12: SOBRA1 | L12: Resize | M12: 389070.2 | N12: 11647370 | O12: 0.033404125
A13: OBBox | B13: UpdateSimpleSize | C13: 1586006 | D13: 11647370 | E13: 0.13616859 | F13: SOBR | G13: UpdateSimpleSize | H13: 1541586.3 | I13: 11647370 | J13: 0.13235488 | K13: SOBRA1 | L13: UpdateSimpleSize | M13: 1532877.1 | N13: 11647370 | O13: 0.13160714
... A15: Octree`1 | B15: Contains | C15: 12419670 | D15: 258319503 | E15: 0.048078717 | F15: Octree`1 | G15: Contains | H15: 12406262 | I15: 258319503 | J15: 0.04802681 | K15: Octree`1 | L15: Contains | M15: 12408308 | N15: 258319503 | O15: 0.048034733
A16: Sum | C16: 7.9222902e+08 | D16: 16810544156 | E16: 0.047126911 | F16: Sum | H16: 8.8199125e+08 | I16: 16810544156 | J16: 0.05246655 | K16: Sum | M16: 7.6278023e+08 | N16: 16810544156 | O16: 0.045375106
A17: Total time elapsed (μs) | C17: 4.6345945e+09 | F17: Total time elapsed (μs) | H17: 4.7163015e+09 | K17: Total time elapsed (μs) | M17: 4.5884408e+09
A19: Class | B19: Euclidean | C19: Baseline | D19: Artifact | F19: Method | G19: SBC.CheckSOBR | H19: SBC.CheckSBC | I19: SBC.Reorient | J19: SBC.Reposition | K19: SBC.Resize | L19: SBC.UpdateSimpleSize | M19: SOBR.CheckSOBR | N19: SOBR.CheckSBC | O19: SOBR.Reorient | P19: SOBR.Reposition | Q19: SOBR.Resize | R19: SOBR.UpdateSimpleSize | S19: Simple.Intersects | T19: CollisionTree.Contains
A20: SBC.CheckSOBR | B20: {=$E$2:$E$16} -> 0.11837644 | C20: {=$J$2:$J$16} -> 0.97358308 | D20: {=$O$2:$O$16} -> 0.21189643 | F20: Euclidean | G20: {=TRANSPOSE($C$2:$C$15/1000000)} -> 10.229298 | H20: 4.9486577 | I20: 2.1276955 | J20: 0.6628026 | K20: 0.3950301 | L20: 0.3039679 | M20: 73.565602 | N20: 7.0224394 | O20: 2.032021 | P20: 0.6579755 | Q20: 0.3838208 | R20: 1.586006 | S20: 675.89404 | T20: 12.41967
A21: SBC.CheckSBC | B21: 0.045093788 | C21: 0.10392392 | D21: 0.040870042 | F21: Baseline | G21: {=TRANSPOSE($H$2:$H$15/1000000)} -> 84.130522 | H21: 11.404762 | I21: 2.005748 | J21: 0.6167372 | K21: 0.3921556 | L21: 0.2976097 | M21: 29.807274 | N21: 56.277155 | O21: 5.7996739 | P21: 0.6134348 | Q21: 0.388116 | R21: 1.5415863 | S21: 676.31021 | T21: 12.406262
A22: SBC.Reorient | B22: 0.17407595 | C22: 0.1640989 | D22: 0.1731893 | F22: Artifact | G22: {=TRANSPOSE($M$2:$M$15/1000000)} -> 18.310669 | H22: 4.4851377 | I22: 2.1168582 | J22: 0.6256696 | K22: 0.3955003 | L22: 0.2960071 | M22: 23.947686 | N22: 12.374986 | O22: 9.6249389 | P22: 0.6158051 | Q22: 0.3890702 | R22: 1.5328771 | S22: 675.65671 | T22: 12.408308
A23: SBC.Reposition | B23: 0.05422674 | C23: 0.050457931 | D23: 0.051188729
A24: SBC.Resize | B24: 0.032319117 | C24: 0.032083941 | D24: 0.032357586 | F24: Function | G24: Sequence 1 calls | H24: Sequence 2 calls | I24: Sequence 3 calls | K24: Sequence 1 % | L24: Sequence 2 % | M24: Sequence 3 % | O24: Euclidean | P24: Baseline | Q24: Artifact | R24: Runtimes | S24: Euclidean | T24: Baseline | U24: Artifact
A25: SBC.UpdateSimpleSize | B25: 0.024868925 | C25: 0.024348734 | D25: 0.024217618 | F25: SBC.CheckSOBR | G25: ='sequence-1-simulation-1'!$D$2 -> 4332776 | H25: ='sequence-2-simulation-1'!$D$2 -> 78233950 | I25: =$D$2 -> 86413296 | J25: SBC.CheckSOBR | K25: {=$G$25:$G$29/$G$29} -> 0.35981282 | L25: {=$H$25:$H$29/$H$29} -> 0.28164726 | M25: {=$I$25:$I$29/$I$29} -> 0.28911149 | O25: =SUM($C$4:$C$7,$C$10:$C$13) -> 8149319.4 | P25: =SUM($H$4:$H$7,$H$10:$H$13) -> 11655062 | Q25: =SUM($M$4:$M$7,$M$10:$M$13) -> 15596726 | R25: Update phase | S25: {=$O$25:$O$29/$P$25:$P$29} -> 0.69920861 | T25: 1 | U25: {=$Q$25:$Q$29/$P$25:$P$29} -> 1.3381934
A26: SOBR.CheckSOBR | B26: 1.6774785 | C26: 0.67967991 | D26: 0.54606675 | F26: SBC.CheckSBC | G26: ='sequence-1-simulation-1'!$D$3 -> 3836730 | H26: ='sequence-2-simulation-1'!$D$3 -> 84091350 | I26: =$D$3 -> 109741450 | J26: SBC.CheckSBC | K26: 0.31861897 | L26: 0.30273427 | M26: 0.36716009 | O26: =SUM($C$2,$C$3,$C$8,$C$9) -> 95765997 | P26: =SUM($H$2,$H$3,$H$8,$H$9) -> 1.8161971e+08 | Q26: =SUM($M$2,$M$3,$M$8,$M$9) -> 59118480 | R26: Narrow phase | S26: 0.52728856 | T26: 1 | U26: 0.32550695
A27: SOBR.CheckSBC | B27: 0.11926085 | C27: 0.95574499 | D27: 0.21016221 | F27: SOBR.CheckSOBR | G27: ='sequence-1-simulation-1'!$D$8 -> 1837830 | H27: ='sequence-2-simulation-1'!$D$8 -> 54315320 | I27: =$D$8 -> 43854870 | J27: SOBR.CheckSOBR | K27: 0.1526215 | L27: 0.19553865 | M27: 0.14672449 | O27: =SUM($C$14,$C$15) -> 6.8831371e+08 | P27: =SUM($H$14,$H$15) -> 6.8871647e+08 | Q27: =SUM($M$14,$M$15) -> 6.8806502e+08 | R27: Broad phase | S27: 0.99941519 | T27: 1 | U27: 0.99905411
A28: SOBR.Reorient | B28: 0.17446179 | C28: 0.4979385 | D28: 0.82636156 | F28: SOBR.CheckSBC | G28: ='sequence-1-simulation-1'!$D$9 -> 2034414 | H28: ='sequence-2-simulation-1'!$D$9 -> 61132190 | I28: =$D$9 -> 58883024 | J28: SOBR.CheckSBC | K28: 0.16894671 | L28: 0.22007982 | M28: 0.19700393 | O28: =$C$16 -> 7.9222902e+08 | P28: =$H$16 -> 8.8199125e+08 | Q28: =$M$16 -> 7.6278023e+08 | R28: Combined | S28: 0.89822776 | T28: 1 | U28: 0.86483877
A29: SOBR.Reposition | B29: 0.056491337 | C29: 0.052667237 | D29: 0.052870742 | F29: Sum | G29: =SUM($G$25:$G$28) -> 12041750 | H29: =SUM($H$25:$H$28) -> 277772810 | I29: =SUM($I$25:$I$28) -> 298892640 | J29: Sum | K29: 1 | L29: 1 | M29: 1 | O29: =$C$17 -> 4.6345945e+09 | P29: =$H$17 -> 4.7163015e+09 | Q29: =$M$17 -> 4.5884408e+09 | R29: Entire simulation | S29: 0.98267562 | T29: 1 | U29: 0.97288962
A30: SOBR.Resize | B30: 0.032953431 | C30: 0.033322201 | D30: 0.033404125
A31: SOBR.UpdateSimpleSize | B31: 0.13616859 | C31: 0.13235488 | D31: 0.13160714
A32: Simple.Intersects | B32: 0.041830688 | C32: 0.041856445 | D32: 0.041816
A33: CollisionTree.Contains | B33: 0.048078717 | C33: 0.04802681 | D33: 0.048034733
A34: Sum | B34: 0.047126911 | C34: 0.05246655 | D34: 0.045375106
A35: Total time elapsed

Sheet simulation-1-summary
A2: Method | B2: Sequence 1 | C2: Sequence 2 | D2: Sequence 3 | F2: Phases | G2: Euclidean | H2: Baseline | I2: Artifact | AO2: Update phase - | AP2: Euclidean | AQ2: Baseline | AR2: Artifact 1
A3: SBC.CheckSOBR - | C3: 2 | F3: Update phase - | J3: 2 | AO3: Sequence 1 | AP3: 0.75497773 | AQ3: 1 | AR3: 1.2650712
A4: Euclidean | B4: 0.13170051 | C4: 0.11799534 | D4: 0.11837644 | F4: Sequence 1 | G4: 0.75497773 | H4: 1 | I4: 1.2650712 | AO4: Sequence 2 | AP4: 0.7154671 | AQ4: 1 | AR4: 1.3207804
A5: Baseline | B5: 1.0035074 | C5: 0.96831688 | D5: 0.97358308 | F5: Sequence 2 | G5: 0.7154671 | H5: 1 | I5: 1.3207804 | AO5: Sequence 3 | AP5: 0.69920861 | AQ5: 1 | AR5: 1.3381934
A6: Artifact | B6: 0.23667231 | C6: 0.20952158 | D6: 0.21189643 | F6: Sequence 3 | G6: 0.69920861 | H6: 1 | I6: 1.3381934
A7: SBC.CheckSBC - | C7: 2 | F7: Narrow phase - | J7: 2 | AO7: Narrow phase - | AP7: Euclidean | AQ7: Baseline | AR7: Artifact 1
A8: Euclidean | B8: 0.050290716 | C8: 0.045279664 | D8: 0.045093788 | F8: Sequence 1 | G8: 0.51463408 | H8: 1 | I8: 0.34291674 | AO8: Sequence 1 | AP8: 0.51463408 | AQ8: 1 | AR8: 0.34291674
A9: Baseline | B9: 0.11322796 | C9: 0.10445559 | D9: 0.10392392 | F9: Sequence 2 | G9: 0.61130049 | H9: 1 | I9: 0.34609215 | AO9: Sequence 2 | AP9: 0.61130049 | AQ9: 1 | AR9: 0.34609215
A10: Artifact | B10: 0.044914602 | C10: 0.040818951 | D10: 0.040870042 | F10: Sequence 3 | G10: 0.52728856 | H10: 1 | I10: 0.32550695 | AO10: Sequence 3 | AP10: 0.52728856 | AQ10: 1 | AR10: 0.32550695
A11: SBC.Reorient - | C11: 2 | F11: Broad phase - | J11: 2
A12: Euclidean | B12: 0.19425419 | C12: 0.17514092 | D12: 0.17407595 | F12: Sequence 1 | G12: 1.0178199 | H12: 1 | I12: 1.02793
A13: Baseline | B13: 0.19115492 | C13: 0.16617562 | D13: 0.1640989 | F13: Sequence 2 | G13: 1.0001378 | H13: 1 | I13: 1.0021978 | AO13: Combined | AP13: Euclidean | AQ13: Baseline | AR13: Artifact 1
A14: Artifact | B14: 0.19807413 | C14: 0.17353108 | D14: 0.1731893 | F14: Sequence 3 | G14: 0.99941519 | H14: 1 | I14: 0.99905411 | AO14: Sequence 1 | AP14: 0.72149338 | AQ14: 1 | AR14: 0.64932839
A15: SBC.Reposition - | C15: 2 | F15: Combined | J15: 2 | AO15: Sequence 2 | AP15: 0.85146293 | AQ15: 1 | AR15: 0.76142039
A16: Euclidean | B16: 0.071025746 | C16: 0.055862599 | D16: 0.05422674 | F16: Sequence 1 | G16: 0.72149338 | H16: 1 | I16: 0.64932839 | AO16: Sequence 3 | AP16: 0.89822776 | AQ16: 1 | AR16: 0.86483877
A17: Baseline | B17: 0.063990867 | C17: 0.051840932 | D17: 0.050457931 | F17: Sequence 2 | G17: 0.85146293 | H17: 1 | I17: 0.76142039
A18: Artifact | B18: 0.066393454 | C18: 0.050752155 | D18: 0.051188729 | F18: Sequence 3 | G18: 0.89822776 | H18: 1 | I18: 0.86483877
A19: SBC.Resize - | C19: 2 | F19: Entire simulation - | J19: 2
A20: Euclidean | B20: 0.036176329 | C20: 0.032541626 | D20: 0.032319117 | F20: Sequence 1 | G20: 1.0012658 | H20: 1 | I20: 1.0006104
A21: Baseline | B21: 0.038399815 | C21: 0.032933441 | D21: 0.032083941 | F21: Sequence 2 | G21: 0.97366611 | H21: 1 | I21: 0.94603972
A22: Artifact | B22: 0.039953803 | C22: 0.032951448 | D22: 0.032357586 | F22: Sequence 3 | G22: 0.98267562 | H22: 1 | I22: 0.97288962
A23: SBC.UpdateSimpleSize - | C23: 2
A24: Euclidean | B24: 0.029279153 | C24: 0.025112199 | D24: 0.024868925
A25: Baseline | B25: 0.027813827 | C25: 0.024418745 | D25: 0.024348734
A26: Artifact | B26: 0.028561326 | C26: 0.024308498 | D26: 0.024217618
A27: SOBR.CheckSOBR - | C27: 2
A28: Euclidean | B28: 1.7629314 | C28: 1.640674 | D28: 1.6774785
A29: Baseline | B29: 0.72986054 | C29: 0.66732959 | D29: 0.67967991
A30: Artifact | B30: 0.61645549 | C30: 0.54065375 | D30: 0.54606675
A31: SOBR.CheckSBC - | C31: 2
A32: Euclidean | B32: 0.13169955 | C32: 0.11749379 | D32: 0.11926085
A33: Baseline | B33: 1.0697312 | C33: 0.94993366 | D33: 0.95574499
A34: Artifact | B34: 0.25339326 | C34: 0.20792539 | D34: 0.21016221
A35: SOBR.Reorient - | C35: 2
A36: Euclidean | B36: 0.20127497 | C36: 0.17465877 | D36: 0.17446179
A37: Baseline | B37: 0.47260604 | C37: 0.45264216 | D37: 0.4979385
A38: Artifact | B38: 0.74440718 | C38: 0.74433658 | D38: 0.82636156
A39: SOBR.Reposition - | C39: 2
A40: Euclidean | B40: 0.081140432 | C40: 0.056398004 | D40: 0.056491337
A41: Baseline | B41: 0.085024477 | C41: 0.053284758 | D41: 0.052667237
...

Sheet sequence-1-simulation-2
A1: Class | B1: Method | C1: Runtime | D1: Calls | E1: Average | F1: Class | G1: Method | H1: Runtime | I1: Calls | J1: Average | K1: Class | L1: Method | M1: Runtime | N1: Calls | O1: Average
A2: SBC | B2: CheckSOBR | C2: 4347972.9 | D2: 4332776 | E2: 1.0035074 | F2: SBCA1 | G2: CheckSOBRA1 | H2: 986375.1 | I2: 4332776 | J2: 0.2276543 | K2: SBCA2 | L2: CheckSOBRA2 | M2: 589198 | N2: 2977515 | O2: 0.19788246
A3: SBC | B3: CheckSBC | C3: 434425.1 | D3: 3836730 | E3: 0.11322796 | F3: SBCA1 | G3: CheckSBCA1 | H3: 782593.3 | I3: 19479496 | J3: 0.040175233 | K3: SBCA2 | L3: CheckSBCA2 | M3: 672602.3 | N3: 16405149 | O3: 0.040999463
A4: SBC | B4: Reorient | C4: 107583.9 | D4: 562810 | E4: 0.19115492 | F4: SBCA1 | G4: Reorient | H4: 106551.5 | I4: 562810 | J4: 0.18932055 | K4: SBCA2 | L4: Reorient | M4: 109051.3 | N4: 562810 | O4: 0.19376219
A5: SBC | B5: Reposition | C5: 36014.7 | D5: 562810 | E5: 0.063990867 | F5: SBCA1 | G5: Reposition | H5: 34777.4 | I5: 562810 | J5: 0.061792434 | K5: SBCA2 | L5: Reposition | M5: 31680.5 | N5: 562810 | O5: 0.056289867
A6: SBC | B6: Resize | C6: 21611.8 | D6: 562810 | E6: 0.038399815 | F6: SBCA1 | G6: Resize | H6: 21613.6 | I6: 562810 | J6: 0.038403013 | K6: SBCA2 | L6: Resize | M6: 22037.3 | N6: 562810 | O6: 0.039155843
A7: SBC | B7: UpdateSimpleSize | C7: 15653.9 | D7: 562810 | E7: 0.027813827 | F7: SBCA1 | G7: UpdateSimpleSize | H7: 15921.2 | I7: 562810 | J7: 0.028288765 | K7: SBCA2 | L7: UpdateSimpleSize | M7: 24647.2 | N7: 562810 | O7: 0.04379311
A8: SOBR | B8: CheckSOBR | C8: 1341359.6 | D8: 1837830 | E8: 0.72986054 | F8: SOBRA1 | G8: CheckSOBRA1 | H8: 1088447.5 | I8: 1837830 | J8: 0.59224602 | K8: SOBRA2 | L8: CheckSOBRA2 | M8: 1483441.9 | N8: 2193690 | O8: 0.67623133
A9: SOBR | B9: CheckSBC | C9: 2176276.2 | D9: 2034414 | E9: 1.0697312 | F9: SOBRA1 | G9: CheckSBCA1 | H9: 490274.6 | I9: 2034414 | J9: 0.24099058 | K9: SOBRA2 | L9: CheckSBCA2 | M9: 444758.2 | N9: 2083505 | O9: 0.21346635
A10: SOBR | B10: Reorient | C10: 264517.6 | D10: 559700 | E10: 0.47260604 | F10: SOBRA1 | G10: Reorient | H10: 404747.4 | I10: 559700 | J10: 0.72315062 | K10: SOBRA2 | L10: Reorient | M10: 398209.3 | N10: 559700 | O10: 0.71146918
A11: SOBR | B11: Reposition | C11: 47588.2 | D11: 559700 | E11: 0.085024477 | F11: SOBRA1 | G11: Reposition | H11: 40966.5 | I11: 559700 | J11: 0.073193675 | K11: SOBRA2 | L11: Reposition | M11: 34890.8 | N11: 559700 | O11: 0.062338396
A12: SOBR | B12: Resize | C12: 26758 | D12: 559700 | E12: 0.047807754 | F12: SOBRA1 | G12: Resize | H12: 26359.9 | I12: 559700 | J12: 0.04709648 | K12: SOBRA2 | L12: Resize | M12: 26269.9 | N12: 559700 | O12: 0.04693568
A13: SOBR | B13: UpdateSimpleSize | C13: 90399.3 | D13: 559700 | E13: 0.16151385 | F13: SOBRA1 | G13: UpdateSimpleSize | H13: 92315.2 | I13: 559700 | J13: 0.16493693 | K13: SOBRA2 | L13: UpdateSimpleSize | M13: 90298.5 | N13: 559700 | O13: 0.16133375
... A15: Octree`1 | B15: Contains | C15: 455219.5 | D15: 8540580 | E15: 0.053300771 | F15: Octree`1 | G15: Contains | H15: 453561.4 | I15: 8540580 | J15: 0.053106627 | K15: SOctree`1 | L15: Contains | M15: 327601.4 | N15: 5255712 | O15: 0.062332449
A16: Sum | C16: 14635296 | D16: 120635800 | E16: 0.12131802 | F16: Sum | H16: 8735253.1 | I16: 116799070 | J16: 0.074788721 | K16: Sum | M16: 7734289.2 | N16: 107469426 | O16: 0.071967344
A17: Total time elapsed (μs) | C17: 182509568 | F17: Total time elapsed (μs): | H17: 1.7946472e+08 | K17: Total time elapsed (μs): | M17: 1.7973714e+08
A19: Class | B19: Baseline | C19: Artifact 1 | D19: Artifact 2 | F19: Method | G19: SBC.CheckSOBR | H19: SBC.CheckSBC | I19: SBC.Reorient | J19: SBC.Reposition | K19: SBC.Resize | L19: SBC.UpdateSimpleSize | M19: SOBR.CheckSOBR | N19: SOBR.CheckSBC | O19: SOBR.Reorient | P19: SOBR.Reposition | Q19: SOBR.Resize | R19: SOBR.UpdateSimpleSize | S19: Simple.Intersects | T19: CollisionTree.Contains | U19: Update phase
A20: SBC.CheckSOBR | B20: {=$E$2:$E$16} -> 1.0035074 | C20: {=$J$2:$J$16} -> 0.2276543 | D20: {=$O$2:$O$16} -> 0.19788246 | F20: Baseline | G20: {=TRANSPOSE($C$2:$C$15/1000000)} -> 4.3479729 | H20: 0.4344251 | I20: 0.1075839 | J20: 0.0360147 | K20: 0.0216118 | L20: 0.0156539 | M20: 1.3413596 | N20: 2.1762762 | O20: 0.2645176 | P20: 0.0475882 | Q20: 0.026758 | R20: 0.0903993 | S20: 5.2699155 | T20: 0.4552195 | U20: =$O$25/1000000 -> 0.6101274
A21: SBC.CheckSBC | B21: 0.11322796 | C21: 0.040175233 | D21: 0.040999463 | F21: Artifact 1 | G21: {=TRANSPOSE($H$2:$H$15/1000000)} -> 0.9863751 | H21: 0.7825933 | I21: 0.1065515 | J21: 0.0347774 | K21: 0.0216136 | L21: 0.0159212 | M21: 1.0884475 | N21: 0.4902746 | O21: 0.4047474 | P21: 0.0409665 | Q21: 0.0263599 | R21: 0.0923152 | S21: 4.1907485 | T21: 0.4535614 | U21: =$P$25/1000000 -> 0.7432527
A22: SBC.Reorient | B22: 0.19115492 | C22: 0.18932055 | D22: 0.19376219 | F22: Artifact 2 | G22: {=TRANSPOSE($M$2:$M$15/1000000)} -> 0.589198 | H22: 0.6726023 | I22: 0.1090513 | J22: 0.0316805 | K22: 0.0220373 | L22: 0.0246472 | M22: 1.4834419 | N22: 0.4447582 | O22: 0.3982093 | P22: 0.0348908 | Q22: 0.0262699 | R22: 0.0902985 | S22: 3.4796026 | T22: 0.3276014 | U22: =$Q$25/1000000 -> 0.7370848
A23: SBC.Reposition | B23: 0.063990867 | C23: 0.061792434 | D23: 0.056289867
A24: SBC.Resize | B24: 0.038399815 | C24: 0.038403013 | D24: 0.039155843 | O24: Baseline | P24: Artifact 1 | Q24: Artifact 2 | R24: Runtimes | S24: Baseline | T24: Artifact 1 | U24: Artifact 2
A25: SBC.UpdateSimpleSize | B25: 0.027813827 | C25: 0.028288765 | D25: 0.04379311 | O25: =SUM($C$4:$C$7,$C$10:$C$13) -> 610127.4 | P25: =SUM($H$4:$H$7,$H$10:$H$13) -> 743252.7 | Q25: =SUM($M$4:$M$7,$M$10:$M$13) -> 737084.8 | R25: Update phase | S25: 1 | T25: =$P$25/$O$25 -> 1.2181926 | U25: =$Q$25/$O$25 -> 1.2080834
A26: SOBR.CheckSOBR | B26: 0.72986054 | C26: 0.59224602 | D26: 0.67623133 | O26: =SUM($C$2,$C$3,$C$8,$C$9) -> 8300033.8 | P26: =SUM($H$2,$H$3,$H$8,$H$9) -> 3347690.5 | Q26: =SUM($M$2,$M$3,$M$8,$M$9) -> 3190000.4 | R26: Narrow phase | S26: 1 | T26: =$P$26/$O$26 -> 0.40333456 | U26: =$Q$26/$O$26 -> 0.38433583
A27: SOBR.CheckSBC | B27: 1.0697312 | C27: 0.24099058 | D27: 0.21346635 | O27: =SUM($C$14,$C$15) -> 5725135 | P27: =SUM($H$14,$H$15) -> 4644309.9 | Q27: =SUM($M$14,$M$15) -> 3807204 | R27: Broad phase | S27: 1 | T27: =$P$27/$O$27 -> 0.81121404 | U27: =$Q$27/$O$27 -> 0.66499812
A28: SOBR.Reorient | B28: 0.47260604 | C28: 0.72315062 | D28: 0.71146918 | O28: =$C$16 -> 14635296 | P28: =$H$16 -> 8735253.1 | Q28: =$M$16 -> 7734289.2 | R28: Combined | S28: 1 | T28: =$P$28/$O$28 -> 0.59686206 | U28: =$Q$28/$O$28 -> 0.52846824
A29: SOBR.Reposition | B29: 0.085024477 | C29: 0.073193675 | D29: 0.062338396 | O29: =$C$17 -> 182509568 | P29: =$H$17 -> 1.7946472e+08 | Q29: =$M$17 -> 1.7973714e+08 | R29: Entire simulation | S29: 1 | T29: =$P$29/$O$29 -> 0.98331676 | U29: =$Q$29/$O$29 -> 0.98480943
A30: SOBR.Resize | B30: 0.047807754 | C30: 0.04709648 | D30: 0.04693568
A31: SOBR.UpdateSimpleSize | B31: 0.16151385 | C31: 0.16493693 | D31: 0.16133375
A32: Simple.Intersects | B32: 0.055145734 | C32: 0.055080597 | D32: 0.046981142
A33: CollisionTree.Contains | B33: 0.053300771 | C33: 0.053106627 | D33: 0.062332449
A34: Sum | B34: 0.12131802 | C34: 0.074788721 | D34: 0.071967344

Sheet sequence-2-simulation-2
A1: Class | B1: Method | C1: Runtime | D1: Calls | E1: Average | F1: Class | G1: Method | H1: Runtime | I1: Calls | J1: Average | K1: Class | L1: Method | M1: Runtime | N1: Calls | O1: Average
A2: SBC | B2: CheckSOBR | C2: 75472284 | D2: 78183158 | E2: 0.96532663 | F2: SBCA1 | G2: CheckSOBRA1 | H2: 16437352 | I2: 78183158 | J2: 0.2102416 | K2: SBCA2 | L2: CheckSOBRA2 | M2: 10811217 | N2: 59438621 | O2: 0.18188876
A3: SBC | B3: CheckSBC | C3: 8741366.7 | D3: 84091350 | E3: 0.10395084 | F3: SBCA1 | G3: CheckSBCA1 | H3: 56810089 | I3: 1542568265 | J3: 0.03682825 | K3: SBCA2 | L3: CheckSBCA2 | M3: 48719108 | N3: 1326851508 | O3: 0.03671783
A4: SBC | B4: Reorient | C4: 1027040.1 | D4: 5814230 | E4: 0.1766425 | F4: SBCA1 | G4: Reorient | H4: 1010469.4 | I4: 5814230 | J4: 0.17379247 | K4: SBCA2 | L4: Reorient | M4: 1011797.6 | N4: 5814230 | O4: 0.17402091
A5: SBC | B5: Reposition | C5: 310509.8 | D5: 5814230 | E5: 0.053405146 | F5: SBCA1 | G5: Reposition | H5: 298571.3 | I5: 5814230 | J5: 0.051351821 | K5: SBCA2 | L5: Reposition | M5: 274024.1 | N5: 5814230 | O5: 0.047129904
A6: SBC | B6: Resize | C6: 192473.3 | D6: 5814230 | E6: 0.033103833 | F6: SBCA1 | G6: Resize | H6: 194197.4 | I6: 5814230 | J6: 0.033400364 | K6: SBCA2 | L6: Resize | M6: 191443.7 | N6: 5814230 | O6: 0.03292675
A7: SBC | B7: UpdateSimpleSize | C7: 141587.1 | D7: 5814230 | E7: 0.024351823 | F7: SBCA1 | G7: UpdateSimpleSize | H7: 144469.9 | I7: 5814230 | J7: 0.024847641 | K7: SBCA2 | L7: UpdateSimpleSize | M7: 208119.2 | N7: 5814230 | O7: 0.0357948
A8: SOBR | B8: CheckSOBR | C8: 36280480 | D8: 54315320 | E8: 0.66796035 | F8: SOBRA1 | G8: CheckSOBRA1 | H8: 29460127 | I8: 54315320 | J8: 0.54239075 | K8: SOBRA2 | L8: CheckSOBRA2 | M8: 41430596 | N8: 66976100 | O8: 0.61858777
A9: SOBR | B9: CheckSBC | C9: 58117441 | D9: 61182982 | E9: 0.94989552 | F9: SOBRA1 | G9: CheckSBCA1 | H9: 12653381 | I9: 61182982 | J9: 0.20681211 | K9: SOBRA2 | L9: CheckSBCA2 | M9: 11455114 | N9: 59535609 | O9: 0.19240777
A10: SOBR | B10: Reorient | C10: 3066870.9 | D10: 6624050 | E10: 0.4629903 | F10: SOBRA1 | G10: Reorient | H10: 5097307.9 | I10: 6624050 | J10: 0.76951531 | K10: SOBRA2 | L10: Reorient | M10: 5015838.6 | N10: 6624050 | O10: 0.7572163
A11: SOBR | B11: Reposition | C11: 347367.3 | D11: 6624050 | E11: 0.05244032 | F11: SOBRA1 | G11: Reposition | H11: 344899.5 | I11: 6624050 | J11: 0.052067768 | K11: SOBRA2 | L11: Reposition | M11: 312926.6 | N11: 6624050 | O11: 0.047240978
A12: SOBR | B12: Resize | C12: 220410.5 | D12: 6624050 | E12: 0.033274281 | F12: SOBRA1 | G12: Resize | H12: 221136 | I12: 6624050 | J12: 0.033383806 | K12: SOBRA2 | L12: Resize | M12: 223576.5 | N12: 6624050 | O12: 0.033752236
A13: SOBR | B13: UpdateSimpleSize | C13: 874131.7 | D13: 6624050 | E13: 0.13196333 | F13: SOBRA1 | G13: UpdateSimpleSize | H13: 882858.2 | I13: 6624050 | J13: 0.13328073 | K13: SOBRA2 | L13: UpdateSimpleSize | M13: 760118.3 | N13: 6624050 | O13: 0.11475129
... A15: Octree`1 | B15: Contains | C15: 6410221.3 | D15: 135039637 | E15: 0.047469183 | F15: Octree`1 | G15: Contains | H15: 6426866.5 | I15: 135039637 | J15: 0.047592445 | K15: SOctree`1 | L15: Contains | M15: 4764157.4 | N15: 97863310 | O15: 0.048681752
A16: Sum | C16: 4.8104239e+08 | D16: 6868319319 | E16: 0.07003786 | F16: Sum | H16: 349553719 | I16: 6784227969 | J16: 0.051524465 | K16: Sum | M16: 3.1776295e+08 | N16: 6199097252 | O16: 0.051259553
A17: Total time elapsed (μs): | C17: 2.1222862e+09 | F17: Total time elapsed (μs): | H17: 1.9627033e+09 | K17: Total time elapsed (μs): | M17: 1.7861558e+09
A19: Class | B19: Baseline | C19: Artifact 1 | D19: Artifact 2 | F19: Method | G19: SBC.CheckSOBR | H19: SBC.CheckSBC | I19: SBC.Reorient | J19: SBC.Reposition | K19: SBC.Resize | L19: SBC.UpdateSimpleSize | M19: SOBR.CheckSOBR | N19: SOBR.CheckSBC | O19: SOBR.Reorient | P19: SOBR.Reposition | Q19: SOBR.Resize | R19: SOBR.UpdateSimpleSize | S19: Simple.Intersects | T19: CollisionTree.Contains | U19: Update phase
A20: SBC.CheckSOBR | B20: {=$E$2:$E$16} -> 0.96532663 | C20: {=$J$2:$J$16} -> 0.2102416 | D20: {=$O$2:$O$16} -> 0.18188876 | F20: Baseline | G20: {=TRANSPOSE($C$2:$C$15/1000000)} -> 75.472284 | H20: 8.7413667 | I20: 1.0270401 | J20: 0.3105098 | K20: 0.1924733 | L20: 0.1415871 | M20: 36.28048 | N20: 58.117441 | O20: 3.0668709 | P20: 0.3473673 | Q20: 0.2204105 | R20: 0.8741317 | S20: 289.8402 | T20: 6.4102213 | U20: =$O$25/1000000 -> 6.1803907
A21: SBC.CheckSBC | B21: 0.10395084 | C21: 0.03682825 | D21: 0.03671783 | F21: Artifact 1 | G21: {=TRANSPOSE($H$2:$H$15/1000000)} -> 16.437352 | H21: 56.810089 | I21: 1.0104694 | J21: 0.2985713 | K21: 0.1941974 | L21: 0.1444699 | M21: 29.460127 | N21: 12.653381 | O21: 5.0973079 | P21: 0.3448995 | Q21: 0.221136 | R21: 0.8828582 | S21: 219.57199 | T21: 6.4268665 | U21: =$P$25/1000000 -> 8.1939096
A22: SBC.Reorient | B22: 0.1766425 | C22: 0.17379247 | D22: 0.17402091 | F22: Artifact 2 | G22: {=TRANSPOSE($M$2:$M$15/1000000)} -> 10.811217 | H22: 48.719108 | I22: 1.0117976 | J22: 0.2740241 | K22: 0.1914437 | L22: 0.2081192 | M22: 41.430596 | N22: 11.455114 | O22: 5.0158386 | P22: 0.3129266 | Q22: 0.2235765 | R22: 0.7601183 | S22: 192.58491 | T22: 4.7641574 | U22: =$Q$25/1000000 -> 7.9978446
A23: SBC.Reposition | B23: 0.053405146 | C23: 0.051351821 | D23: 0.047129904
A24: SBC.Resize | B24: 0.033103833 | C24: 0.033400364 | D24: 0.03292675 | O24: Baseline | P24: Artifact 1 | Q24: Artifact 2 | R24: Runtimes | S24: Baseline | T24: Artifact 1 | U24: Artifact 2
A25: SBC.UpdateSimpleSize | B25: 0.024351823 | C25: 0.024847641 | D25: 0.0357948 | O25: =SUM($C$4:$C$7,$C$10:$C$13) -> 6180390.7 | P25: =SUM($H$4:$H$7,$H$10:$H$13) -> 8193909.6 | Q25: =SUM($M$4:$M$7,$M$10:$M$13) -> 7997844.6 | R25: Update phase | S25: 1 | T25: =$P$25/$O$25 -> 1.3257915 | U25: =$Q$25/$O$25 -> 1.2940678
A26: SOBR.CheckSOBR | B26: 0.66796035 | C26: 0.54239075 | D26: 0.61858777 | O26: =SUM($C$2,$C$3,$C$8,$C$9) -> 1.7861157e+08 | P26: =SUM($H$2,$H$3,$H$8,$H$9) -> 1.1536095e+08 | Q26: =SUM($M$2,$M$3,$M$8,$M$9) -> 1.1241604e+08 | R26: Narrow phase | S26: 1 | T26: =$P$26/$O$26 -> 0.64587613 | U26: =$Q$26/$O$26 -> 0.62938831
A27: SOBR.CheckSBC | B27: 0.94989552 | C27: 0.20681211 | D27: 0.19240777 | O27: =SUM($C$14,$C$15) -> 2.9625042e+08 | P27: =SUM($H$14,$H$15) -> 2.2599886e+08 | Q27: =SUM($M$14,$M$15) -> 1.9734907e+08 | R27: Broad phase | S27: 1 | T27: =$P$27/$O$27 -> 0.76286426 | U27: =$Q$27/$O$27 -> 0.66615625
A28: SOBR.Reorient | B28: 0.4629903 | C28: 0.76951531 | D28: 0.7572163 | O28: =$C$16 -> 4.8104239e+08 | P28: =$H$16 -> 349553719 | Q28: =$M$16 -> 3.1776295e+08 | R28: Combined | S28: 1 | T28: =$P$28/$O$28 -> 0.72665888 | U28: =$Q$28/$O$28 -> 0.66057163
A29: SOBR.Reposition | B29: 0.05244032 | C29: 0.052067768 | D29: 0.047240978 | O29: =$C$17 -> 2.1222862e+09 | P29: =$H$17 -> 1.9627033e+09 | Q29: =$M$17 -> 1.7861558e+09 | R29: Entire simulation | S29: 1 | T29: =$P$29/$O$29 -> 0.92480614 | U29: =$Q$29/$O$29 -> 0.84161869
A30: SOBR.Resize | B30: 0.033274281 | C30: 0.033383806 | D30: 0.033752236
A31: SOBR.UpdateSimpleSize | B31: 0.13196333 | C31: 0.13328073 | D31: 0.11475129
A32: Simple.Intersects | B32: 0.045246854 | C32: 0.045149829 | D32: 0.042431931
A33: CollisionTree.Contains | B33: 0.047469183 | C33: 0.047592445 | D33: 0.048681752
A34: Sum | B34: 0.07003786 | C34: 0.051524465 | D34: 0.051259553

Sheet sequence-3-simulation-2
A1: Class | B1: Method | C1: Runtime | D1: Calls | E1: Average | F1: Class | G1: Method | H1: Runtime | I1: Calls | J1: Average | K1: Class | L1: Method | M1: Runtime | N1: Calls | O1: Average
A2: SBC | B2: CheckSOBR | C2: 83877804 | D2: 86388893 | E2: 0.97093273 | F2: SBCA1 | G2: CheckSOBRA1 | H2: 18289793 | I2: 86388893 | J2: 0.21171464 | K2: SBCA2 | L2: CheckSOBRA2 | M2: 11749948 | N2: 62381810 | O2: 0.18835535
A3: SBC | B3: CheckSBC | C3: 11348454 | D3: 109741450 | E3: 0.10341083 | F3: SBCA1 | G3: CheckSBCA1 | H3: 1.7188646e+08 | I3: 4675658158 | J3: 0.036761983 | K3: SBCA2 | L3: CheckSBCA2 | M3: 1.4265227e+08 | N3: 3891693750 | O3: 0.036655574
A4: SBC | B4: Reorient | C4: 2151399.3 | D4: 12222800 | E4: 0.17601526 | F4: SBCA1 | G4: Reorient | H4: 2113057 | I4: 12222800 | J4: 0.17287831 | K4: SBCA2 | L4: Reorient | M4: 2137638.7 | N4: 12222800 | O4: 0.17488944
A5: SBC | B5: Reposition | C5: 628535.8 | D5: 12222800 | E5: 0.051423225 | F5: SBCA1 | G5: Reposition | H5: 625144.8 | I5: 12222800 | J5: 0.051145793 | K5: SBCA2 | L5: Reposition | M5: 575686.5 | N5: 12222800 | O5: 0.047099396
A6: SBC | B6: Resize | C6: 397121.6 | D6: 12222800 | E6: 0.032490231 | F6: SBCA1 | G6: Resize | H6: 399498.1 | I6: 12222800 | J6: 0.032684663 | K6: SBCA2 | L6: Resize | M6: 394379.9 | N6: 12222800 | O6: 0.032265921
A7: SBC | B7: UpdateSimpleSize | C7: 294599.9 | D7: 12222800 | E7: 0.024102489 | F7: SBCA1 | G7: UpdateSimpleSize | H7: 299842.8 | I7: 12222800 | J7: 0.024531433 | K7: SBCA2 | L7: UpdateSimpleSize | M7: 427294.6 | N7: 12222800 | O7: 0.034958815
A8: SOBR | B8: CheckSOBR | C8: 29692521 | D8: 43854870 | E8: 0.67706326 | F8: SOBRA1 | G8: CheckSOBRA1 | H8: 24040370 | I8: 43854870 | J8: 0.54818017 | K8: SOBRA2 | L8: CheckSOBRA2 | M8: 36325279 | N8: 56211700 | O8: 0.64622275
A9: SOBR | B9: CheckSBC | C9: 55787864 | D9: 58907427 | E9: 0.94704296 | F9: SOBRA1 | G9: CheckSBCA1 | H9: 12275388 | I9: 58907427 | J9: 0.20838438 | K9: SOBRA2 | L9: CheckSBCA2 | M9: 12052665 | N9: 62068610 | O9: 0.19418293
A10: SOBR | B10: Reorient | C10: 5851939.3 | D10: 11647370 | E10: 0.50242581 | F10: SOBRA1 | G10: Reorient | H10: 9565154 | I10: 11647370 | J10: 0.82122866 | K10: SOBRA2 | L10: Reorient | M10: 9356731.2 | N10: 11647370 | O10: 0.80333425
A11: SOBR | B11: Reposition | C11: 603654.1 | D11: 11647370 | E11: 0.051827503 | F11: SOBRA1 | G11: Reposition | H11: 604566.7 | I11: 11647370 | J11: 0.051905855 | K11: SOBRA2 | L11: Reposition | M11: 553279.4 | N11: 11647370 | O11: 0.047502518
A12: SOBR | B12: Resize | C12: 387015.6 | D12: 11647370 | E12: 0.033227724 | F12: SOBRA1 | G12: Resize | H12: 385250.1 | I12: 11647370 | J12: 0.033076145 | K12: SOBRA2 | L12: Resize | M12: 391519.4 | N12: 11647370 | O12: 0.033614404
A13: SOBR | B13: UpdateSimpleSize | C13: 1531679.6 | D13: 11647370 | E13: 0.13150433 | F13: SOBRA1 | G13: UpdateSimpleSize | H13: 1533959 | I13: 11647370 | J13: 0.13170003 | K13: SOBRA2 | L13: UpdateSimpleSize | M13: 1233150.5 | N13: 11647370 | O13: 0.10587373
... A15: Octree`1 | B15: Contains | C15: 12409742 | D15: 258322343 | E15: 0.048039756 | F15: Octree`1 | G15: Contains | H15: 12537466 | I15: 258322343 | J15: 0.048534191 | K15: SOctree`1 | L15: Contains | M15: 10944407 | N15: 233406193 | O15: 0.046889958
A16: Sum | C16: 8.8265981e+08 | D16: 16751706607 | E16: 0.05269074 | F16: Sum | H16: 7.3110964e+08 | I16: 16641965157 | J16: 0.043931689 | K16: Sum | M16: 6.7890329e+08 | N16: 15028727770 | O16: 0.045173703
A17: Total time elapsed (μs): | C17: 4.6827335e+09 | F17: Total time elapsed (μs): | H17: 4.2887732e+09 | K17: Total time elapsed (μs): | M17: 4.0654919e+09
A19: Class | B19: Baseline | C19: Artifact 1 | D19: Artifact 2 | F19: Method | G19: SBC.CheckSOBR | H19: SBC.CheckSBC | I19: SBC.Reorient | J19: SBC.Reposition | K19: SBC.Resize | L19: SBC.UpdateSimpleSize | M19: SOBR.CheckSOBR | N19: SOBR.CheckSBC | O19: SOBR.Reorient | P19: SOBR.Reposition | Q19: SOBR.Resize | R19: SOBR.UpdateSimpleSize | S19: Simple.Intersects | T19: CollisionTree.Contains | U19: Update phase
A20: SBC.CheckSOBR | B20: {=$E$2:$E$16} -> 0.97093273 | C20: {=$J$2:$J$16} -> 0.21171464 | D20: {=$O$2:$O$16} -> 0.18835535 | F20: Baseline | G20: {=TRANSPOSE($C$2:$C$15/1000000)} -> 83.877804 | H20: 11.348454 | I20: 2.1513993 | J20: 0.6285358 | K20: 0.3971216 | L20: 0.2945999 | M20: 29.692521 | N20: 55.787864 | O20: 5.8519393 | P20: 0.6036541 | Q20: 0.3870156 | R20: 1.5316796 | S20: 677.69748 | T20: 12.409742 | U20: =$O$25/1000000 -> 11.845945
A21: SBC.CheckSBC | B21: 0.10341083 | C21: 0.036761983 | D21: 0.036655574 | F21: Artifact 1 | G21: {=TRANSPOSE($H$2:$H$15/1000000)} -> 18.289793 | H21: 171.88646 | I21: 2.113057 | J21: 0.6251448 | K21: 0.3994981 | L21: 0.2998428 | M21: 24.04037 | N21: 12.275388 | O21: 9.565154 | P21: 0.6045667 | Q21: 0.3852501 | R21: 1.533959 | S21: 476.55369 | T21: 12.537466 | U21: =$P$25/1000000 -> 15.526472
A22: SBC.Reorient | B22: 0.17601526 | C22: 0.17287831 | D22: 0.17488944 | F22: Artifact 2 | G22: {=TRANSPOSE($M$2:$M$15/1000000)} -> 11.749947 | H22: 142.65227 | I22: 2.1376387 | J22: 0.5756865 | K22: 0.3943799 | L22: 0.4272946 | M22: 36.325279 | N22: 12.052665 | O22: 9.3567312 | P22: 0.5532794 | Q22: 0.3915194 | R22: 1.2331505 | S22: 450.10904 | T22: 10.944407 | U22: =$Q$25/1000000 -> 15.06968
A23: SBC.Reposition | B23: 0.051423225 | C23: 0.051145793 | D23: 0.047099396
A24: SBC.Resize | B24: 0.032490231 | C24: 0.032684663 | D24: 0.032265921 | O24: Baseline | P24: Artifact 1 | Q24: Artifact 2 | R24: Runtimes | S24: Baseline | T24: Artifact 1 | U24: Artifact 2
A25: SBC.UpdateSimpleSize | B25: 0.024102489 | C25: 0.024531433 | D25: 0.034958815 | O25: =SUM($C$4:$C$7,$C$10:$C$13) -> 11845945 | P25: =SUM($H$4:$H$7,$H$10:$H$13) -> 15526472 | Q25: =SUM($M$4:$M$7,$M$10:$M$13) -> 15069680 | R25: Update phase | S25: 1 | T25: =$P$25/$O$25 -> 1.3106993 | U25: =$Q$25/$O$25 -> 1.2721383
A26: SOBR.CheckSOBR | B26: 0.67706326 | C26: 0.54818017 | D26: 0.64622275 | O26: =SUM($C$2,$C$3,$C$8,$C$9) -> 1.8070664e+08 | P26: =SUM($H$2,$H$3,$H$8,$H$9) -> 2.2649202e+08 | Q26: =SUM($M$2,$M$3,$M$8,$M$9) -> 202780160 | R26: Narrow phase | S26: 1 | T26: =$P$26/$O$26 -> 1.2533685 | U26: =$Q$26/$O$26 -> 1.1221511
A27: SOBR.CheckSBC | B27: 0.94704296 | C27: 0.20838438 | D27: 0.19418293 | O27: =SUM($C$14,$C$15) -> 6.9010723e+08 | P27: =SUM($H$14,$H$15) -> 4.8909116e+08 | Q27: =SUM($M$14,$M$15) -> 4.6105345e+08 | R27: Broad phase | S27: 1 | T27: =$P$27/$O$27 -> 0.70871763 | U27: =$Q$27/$O$27 -> 0.66808959
A28: SOBR.Reorient | B28: 0.50242581 | C28: 0.82122866 | D28: 0.80333425 | O28: =$C$16 -> 8.8265981e+08 | P28: =$H$16 -> 7.3110964e+08 | Q28: =$M$16 -> 6.7890329e+08 | R28: Combined | S28: 1 | T28: =$P$28/$O$28 -> 0.82830286 | U28: =$Q$28/$O$28 -> 0.76915623
A29: SOBR.Reposition | B29: 0.051827503 | C29: 0.051905855 | D29: 0.047502518 | O29: =$C$17 -> 4.6827335e+09 | P29: =$H$17 -> 4.2887732e+09 | Q29: =$M$17 -> 4.0654919e+09 | R29: Entire simulation | S29: 1 | T29: =$P$29/$O$29 -> 0.91586958 | U29: =$Q$29/$O$29 -> 0.86818775
A30: SOBR.Resize | B30: 0.033227724 | C30: 0.033076145 | D30: 0.033614404
A31: SOBR.UpdateSimpleSize | B31: 0.13150433 | C31: 0.13170003 | D31: 0.10587373
A32: Simple.Intersects | B32: 0.042095597 | C32: 0.041717497 | D32: 0.042353298
A33: CollisionTree.Contains | B33: 0.048039756 | C33: 0.048534191 | D33: 0.046889958
A34: Sum | B34: 0.05269074 | C34: 0.043931689 | D34: 0.045173703

Sheet simulation-2-summary
A2: Method | B2: Sequence 1 | C2: Sequence 2 | D2: Sequence 3 | F2: Update phase | G2: Baseline | H2: Artifact 1 | I2: Artifact 2
A3: SBC.CheckSOBR | C3: 2 | F3: Sequence 1 | G3: 1 | H3: 1.2181926 | I3: 1.2080834
A4: Baseline | B4: 1.0035074 | C4: 0.96532663 | D4: 0.97093273 | F4: Sequence 2 | G4: 1 | H4: 1.3257915 | I4: 1.2940678
A5: Artifact 1 | B5: 0.2276543 | C5: 0.2102416 | D5: 0.21171464 | F5: Sequence 3 | G5: 1 | H5: 1.3106993 | I5: 1.2721383
A6: Artifact 2 | B6: 0.19788246 | C6: 0.18188876 | D6: 0.18835535
A7: SBC.CheckSBC | C7: 2 | F7: Narrow phase | G7: Baseline | H7: Artifact 1 | I7: Artifact 2
A8: Baseline | B8: 0.11322796 | C8: 0.10395084 | D8: 0.10341083 | F8: Sequence 1 | G8: 1 | H8: 0.40333456 | I8: 0.38433583
A9: Artifact 1 | B9: 0.040175233 | C9: 0.03682825 | D9: 0.036761983 | F9: Sequence 2 | G9: 1 | H9: 0.64587613 | I9: 0.62938831
A10: Artifact 2 | B10: 0.040999463 | C10: 0.03671783 | D10: 0.036655574 | F10: Sequence 3 | G10: 1 | H10: 1.2533685 | I10: 1.1221511
A11: SBC.UpdateSimpleSize | C11: 2
A12: Baseline | B12: 0.027813827 | C12: 0.024351823 | D12: 0.024102489 | F12: Broad phase | G12: Baseline | H12: Artifact 1 | I12: Artifact 2
A13: Artifact 1 | B13: 0.028288765 | C13: 0.024847641 | D13: 0.024531433 | F13: Sequence 1 | G13: 1 | H13: 0.81121404 | I13: 0.66499812
A14: Artifact 2 | B14: 0.04379311 | C14: 0.0357948 | D14: 0.034958815 | F14: Sequence 2 | G14: 1 | H14: 0.76286426 | I14: 0.66615625
A15: SOBR.CheckSOBR | C15: 2 | F15: Sequence 3 | G15: 1 | H15: 0.70871763 | I15: 0.66808959
A16: Baseline | B16: 0.72986054 | C16: 0.66796035 | D16: 0.67706326
A17: Artifact 1 | B17: 0.59224602 | C17: 0.54239075 | D17: 0.54818017 | F17: Combined | G17: Baseline | H17: Artifact 1 | I17: Artifact 2
A18: Artifact 2 | B18: 0.67623133 | C18: 0.61858777 | D18: 0.64622275 | F18: Sequence 1 | G18: 1 | H18: 0.59686206 | I18: 0.52846824
A19: SOBR.CheckSBC | C19: 2 | F19: Sequence 2 | G19: 1 | H19: 0.72665888 | I19: 0.66057163
A20: Baseline | B20: 1.0697312 | C20: 0.94989552 | D20: 0.94704296 | F20: Sequence 3 | G20: 1 | H20: 0.82830286 | I20: 0.76915623
A21: Artifact 1 | B21: 0.24099058 | C21: 0.20681211 | D21: 0.20838438
A22: Artifact 2 | B22: 0.21346635 | C22: 0.19240777 | D22: 0.19418293 | F22: Entire simulation | G22: Baseline | H22: Artifact 1 | I22: Artifact 2
A23: SOBR.UpdateSimpleSize | C23: 2 | F23: Sequence 1 | G23: 1 | H23: 0.98331676 | I23: 0.98480943
A24: Baseline | B24: 0.16151385 | C24: 0.13196333 | D24: 0.13150433 | F24: Sequence 2 | G24: 1 | H24: 0.92480614 | I24: 0.84161869
A25: Artifact 1 | B25: 0.16493693 | C25: 0.13328073 | D25: 0.13170003 | F25: Sequence 3 | G25: 1 | H25: 0.91586958 | I25: 0.86818775
A26: Artifact 2 | B26: 0.16133375 | C26: 0.11475129 | D26: 0.10587373
A27: Simple.Intersects | C27: 2
A28: Baseline | B28: 0.055145734 | C28: 0.045246854 | D28: 0.042095597 | F28: Narrow phase Calls
A29: Artifact 1 | B29: 0.055080597 | C29: 0.045149829 | D29: 0.041717497 | F29: Implementation | G29: SBC.CheckSOBR | H29: SBC.CheckSBC | I29: SOBR.CheckSOBR | J29: SOBR.CheckSBC
A30: Artifact 2 | B30: 0.046981142 | C30: 0.042431931 | D30: 0.042353298 | F30: Sequence 1 Baseline | G30: 4332776 | H30: 3836730 | I30: 1837830 | J30: 2034414
A31: CollisionTree.Contains | C31: 2 | F31: Sequence 1 Artifact 1 | G31: 4332776 | H31: 19479496 | I31: 1837830 | J31: 2034414
A32: Baseline | B32: 0.053300771 | C32: 0.047469183 | D32: 0.048039756 | F32: Sequence 1 Artifact 2 | G32: 2977515 | H32: 16405149 | I32: 2193690 | J32: 2083505
A33: Artifact 1 | B33: 0.053106627 | C33: 0.047592445 | D33: 0.048534191 | F33: Sequence 2 Baseline | G33: 78183158 | H33: 84091350 | I33: 54315320 | J33: 61182982
A34: Artifact 2 | B34: 0.062332449 | C34: 0.048681752 | D34: 0.046889958 | F34: Sequence 2 Artifact 1 | G34: 78183158 | H34: 1542568265 | I34: 54315320 | J34: 61182982
C35: 2 | F35: Sequence 2 Artifact 2 | G35: 59438621 | H35: 1326851508 | I35: 66976100 | J35: 59535609
F36: Sequence 3 Baseline | G36: 86388893 | H36: 109741450 | I36: 43854870 | J36: 58907427
F37: Sequence 3 Artifact 1 | G37: 86388893 | H37: 4675658158 | I37: 43854870 | J37: 58907427
F38: Sequence 3 Artifact 2 | G38: 62381810 | H38: 3891693750 | I38: 56211700 | J38: 62068610
F43: Broad Phase Calls
F44: Implementation | G44: Baseline | H44: Artifact 1 | I44: Artifact 2
F45: Sequence 1 Simple.Intersects | G45: 95563430 | H45: 76083934 | I45: 74063815
...
